Workbook
Name _xlchart.v2.11: 'Step 5'!$G$78
Name _xlchart.v2.22: 'Step 5'!$B$82:$G$82
Name _xlchart.v1.26: 'Step 5'!$A$81
Name _xlchart.v2.7: 'Step 5'!$E$78
Name _xlchart.v2.1: 'Step 5'!$B$78
Name _xlchart.v2.20: 'Step 5'!$B$80:$G$80
Name _xlchart.v2.5: 'Step 5'!$D$78
Name _xlchart.v2.2: 'Step 5'!$B$79:$B$83
Name _xlchart.v2.15: 'Step 5'!$A$81
Name _xlchart.v2.13: 'Step 5'!$A$79
Name _xlchart.v2.3: 'Step 5'!$C$78
Name _xlchart.v1.32: 'Step 5'!$B$81:$G$81
Name _xlchart.v2.4: 'Step 5'!$C$79:$C$83
Name _xlchart.v2.14: 'Step 5'!$A$80
Name _xlchart.v2.0: 'Step 5'!$A$79:$A$83
Name _xlchart.v2.16: 'Step 5'!$A$82
Name _xlchart.v1.29: 'Step 5'!$B$78:$G$78
Name _xlchart.v2.19: 'Step 5'!$B$79:$G$79
Name _xlchart.v2.10: 'Step 5'!$F$79:$F$83
Name _xlchart.v2.23: 'Step 5'!$B$83:$G$83
Name _xlchart.v1.30: 'Step 5'!$B$79:$G$79
Name _xlchart.v2.17: 'Step 5'!$A$83
Name _xlchart.v2.6: 'Step 5'!$D$79:$D$83
Name _xlchart.v2.12: 'Step 5'!$G$79:$G$83
Name _xlchart.v1.33: 'Step 5'!$B$82:$G$82
Name _xlchart.v1.34: 'Step 5'!$B$83:$G$83
Name _xlchart.v1.27: 'Step 5'!$A$82
Name _xlchart.v1.28: 'Step 5'!$A$83
Name _xlchart.v1.24: 'Step 5'!$A$79
Name _xlchart.v2.21: 'Step 5'!$B$81:$G$81
Name _xlchart.v1.25: 'Step 5'!$A$80
Name _xlchart.v2.18: 'Step 5'!$B$78:$G$78
Name _xlchart.v2.9: 'Step 5'!$F$78
Name _xlchart.v2.8: 'Step 5'!$E$79:$E$83
Name _xlchart.v1.31: 'Step 5'!$B$80:$G$80

Sheet Instruction
A3: Detail
A4: This worksheet is designed to support the decision-making process by identifying the key considerations for expanding into projects in a new country.
A6: The five-step decision flow draws on the OECD blended finance framework, incorporates RPA-specific priorities, and is informed by various publicly available blended finance sources:
A7: Step 1 | B7: Identify and Define the Development Challenges
A8: Step 2 | B8: Map the intermediaries already addressing the issue
A9: Step 3 | B9: Diagnose the project stage and barriers
A10: Step 4 | B10: Recommend blended finance tool
A11: Step 5 | B11: Recommend a global expansion option for RPA

Sheet Step 1
A1: =Instruction!A7 -> Step 1 | B1: =Instruction!B7 -> Identify and Define the Development Challenges
A2: Identify the key environmental, social, and/or economic issues in the country, and assess how these issues create a clear development rationale for intervention. In line with Blended Finance Principle 1: Anchor blended finance to a development rationale.
A3: 1 | B3: Use development finance in blended finance as a driver to maximise development outcomes and impact
A4: 2 | B4: Define development objectives and expected results as the basis for deploying development finance
A5: 3 | B5: Demonstrate a commitment to high quality
A6: This process can be informed by desk research, interviews with local stakeholders, and analysis using the SDG framework or each country's Nationally Determined Contributions (NDCs) as a part of Paris Agreement compliance target.
A8: SDG | C8: Description
A9: 1 - No poverty | C9: End poverty in all its forms everywhere
A10: 2 - Zero hunger | C10: End hunger, achieve food security and improved nutrition and promote sustainable agriculture
A11: 3 - Good health and well-being | C11: Ensure healthy lives and promote well-being for all at all ages
A12: 4 - Quality education | C12: Ensure inclusive and equitable quality education and promote lifelong learning opportunities for all
A13: 5 - Gender equality | C13: Achieve gender equality and empower all women and girls
A14: 6 - Clean water and sanitation | C14: Ensure availability and sustainable management of water and sanitation for all
A15: 7 - Affordable and clean energy | C15: Ensure access to affordable, reliable, sustainable and modern energy for all
A16: 8 - Decent work and economic growth | C16: Promote sustained, inclusive and sustainable economic growth, full and productive employment and decent work for all
A17: 9 - Industry, innovation, and infrastructure | C17: Build resilient infrastructure, promote inclusive and sustainable industrialization and foster innovation
A18: 10 - Reduced inequalities | C18: Reduce inequality within and among countries
A19: 11 - Sustainable cities and communities | C19: Make cities and human settlements inclusive, safe, resilient and sustainable
... A25: 17 - Partnerships for the goals | C25: Strengthen the means of implementation and revitalize the Global Partnership for Sustainable Development
A27: Worksheet for Step 1
A28: Country | B28: SDG Goals/NDCs Target | C28: Country Challenges | D28: Background Information | E28: Project Name | F28: Launch Year | G28: Size | H28: Model | I28: Development Rationale | J28: Expected Results | K28: Quality/Safeguards | L28: Sources
A29: Enter the target country being assessed | B29: Identify the most relevant SDG(s) and, where applicable, the related NDC priority connected to the issue | C29: Summarize the main challenges affecting the country | D29: Briefly explain the issue using key facts, trends, and context to show why it matters | E29: State the project name that addressing the country challenges | F29: Indicate the year the project was launched. | G29: Specify the project size. | H29: Describe the project model/program. | I29: Describe why this challenge justifies development intervention and why additional support may still be needed | J29: State the intended development outcomes and what success would look like | K29: Note key safeguards or quality factors such as inclusiveness, stakeholder alignment, ESG considerations, transparency, and accountability | L29: Provide credible references for all key data, claims, and examples used in the row
A30: Japan | B30: 3 - Good health and well-being | C30: Aging Population | D30: - Japan is one of the world’s most aged societies. In 2023, 29.1% of the population was aged 65+, while the working-age population fell to 59.5%. Total Fertility Rate: 1.20 (2023). Total population: 123.75 million (2024) and continues declining. - This creates pressure on care systems. More older people need care, while fewer workers are available to provide. By 2040, Japan may need 690,000 additional nursing-care workers according to MHLW. Healthcare and long-term care costs are rising. Japan spends 11.5% of GDP on health, above the OECD average. Social security spending exceeds 36% of national expenditure (FY2023). | E30: Toyota City’s “Zutto Genki! Project” | F30: 2021 | G30: 5-year project; July 2021-June 2026; up to JPY 500 million; expected 5,000 participants/year, or 25,000 participants over 5 years | H30: - The project addresses a real and urgent aging-society challenge on how to prevent or delay the need for long-term care among older residents by increasing social participation, physical activity, community engagement, and a sense of purpose in life. - However, the project’s core value is generated mainly as a public and social benefit rather than as direct commercial revenue. In practice, this means the city and its partners must prove that a broad preventive-care intervention can translate into measurable future reductions in long-term care expenditure, even though the causal chain is long, the benefits accrue over time, and participant uptake and retention require active management. - The project uses a Social Impact Bond / Pay-for-Success model for elderly care prevention. Toyota City contracts a private coordinator to manage health-promotion and social-participation programs for older residents. Private companies and service providers deliver activities such as exercise, hobbies, community, and wellness programs. Payment is linked to outcomes, especially reducing the need for long-term care and lowering future public care costs. In short, the model shifts the project from normal public-service spending into an outcome-based prevention program, where public money is used more efficiently if measurable social results are achieved | I30: - Japan is responding through community-based integrated care. The approach combines healthcare, long-term care, prevention, housing, and daily-life support. - Toyota City’s “Zutto Genki! Project” is relevant because it uses a preventive-care model to support healthy ageing, increase social participation, and potentially reduce future long-term care costs. | J30: - create a cost-saving for long-term healthcare. According to the 11-year prospective cohort study of healthy Japanese older adults, compared with non-participants, respondents who took part in hobby groups or sports activities once a week incurred lower costs for LTCI services (approximately US$3.5 and US$6.1 thousand, respectively, per person), even after demographic variables and health status at baseline were controlled. | K30: - Government involvement to support elderly healthcare policy and broader quality considerations around public delivery, accountability, and social inclusion | L30: https://www.stat.go.jp/english/data/jinsui/2023np/index.html https://www.mhlw.go.jp/content/10807000/001303599.pdf https://www.city.toyota.aichi.jp/_res/projects/default_project/_page_/001/044/582/r0604/01.pdf https://www.oecd.org/content/dam/oecd/en/publications/reports/2025/07/health-at-a-glance-2023_39bcb58d/japan_0b0de6bb/1b4f5f1d-en.pdf https://www.oecd.org/content/dam/oecd/en/publications/reports/2024/01/oecd-economic-surveys-japan-2024_9289b572/41e807f9-en.pdf https://www.mhlw.go.jp/content/10500000/000591805.pdf https://www.city.toyota.aichi.jp/_res/projects/default_project/page/001/058/887/02.pdf https://www.clair.or.jp/j/library/docs/2021he-toyota.pdf https://www.dreamincubator.com/sea/the-zutto-genki-project-a-500-million-healthy-ageing-social-impact-bond-in-toyota-city
A31: Indonesia | B31: 7 - Affordable and clean energy | C31: Clean energy for villages | D31: - Indonesia’s challenge is no longer mainly basic electricity access. National electrification had already reached 99.83% in 2024. - The bigger issue is meeting rising power demand with cleaner supply. Electricity sales reached 303.4 TWh in 2024. Demand is projected to reach around 445 TWh by 2030 under current planning trajectories. - Some regions still need special attention. ESDM has highlighted East Nusa Tenggara, Maluku, and Papua for particular attention. This creates a financing gap for small clean-energy projects. Many projects are developmentally important, but still too small, risky, or weakly structured for normal commercial debt. | E31: Pandanduri Mini Hydro Power Plant | F31: 2023 | G31: Part of three hydropower projects totaling 7 MW capacity; total CAPEX IDR 210 billion; UK-MENTARI grant IDR 21 billion; uses existing dam infrastructure | H31: - At the project’s current stage, the core issue is no longer whether Pandanduri is too early to finance. Construction was reported at 97% by March 2025, so the more relevant diagnosis is whether the project’s operating economics, repayment profile, and risk allocation are strong enough to justify capital on sustainable terms as it moves into completion and operations. In other words, the central problem is no longer basic investability, but whether a small renewable-energy asset with limited scale can generate returns attractive enough and sufficiently protected against downside risks for private capital without continued concessional support. - The project uses a blended finance model with viability gap funding. The mini hydro project generates renewable electricity by using existing public dam infrastructure, thereby reducing construction complexity and improving project feasibility. PT SMI provides debt financing, while the UK-MENTARI grant helps close the funding gap and make the project more bankable. In short, the model combines commercial loan financing with concessional grant support to de-risk a small renewable energy project that may otherwise be too small, too risky, or financially weak for conventional commercial debt. | I31: - That is why catalytic capital matters. SDG Indonesia One was designed as a blended-finance platform to combine public and private capital and support sustainable infrastructure. Pandanduri is a strong example. It is a real infrastructure project with a clear financing gap, identified catalytic support, named donors/lenders, and measurable implementation progress. PT SMI states the project had been delayed for years due to commercial feasibility constraints, and that grant support helped it finally reach financial close | J31: - Pandanduri able to reach renewable energy capacity of 2 x 290 kW. Indonesia will be able to reach 75 GW of clean energy by 2040. | K31: - Quality considerations center on project bankability, donor and lender coordination, and disciplined use of catalytic support so concessional funding closes real viability gaps without over-subsidizing projects | L31: https://www.esdm.go.id/assets/media/content/content-handbook-of-energy-and-economic-statistics-of-indonesia-2024.pdf https://www.esdm.go.id/en/berita-unit/directorate-general-of-electricity/ruptl-2021-2030-diterbitkan-porsi-ebt-diperbesar https://web.pln.co.id/statics/uploads/2025/06/b967d-ruptl-pln-2025-2034-pub-.pdf https://energyandcleanair.org/wp/wp-content/uploads/2025/09/CREA_EN-IDN-Briefing-Indonesias-RUPTL-2025-2034_-Fossils-first-renewables-later.pdf https://ember-energy.org/latest-insights/indonesias-expansion-of-clean-power-can-spur-growth-and-equality/ https://www.esdm.go.id/en/media-center/news-archives/bigger-share-given-to-renewables-in-2021-2030-electricity-procurement-plan https://www.ptsmi.co.id/statement-on-climate-change-issue https://www.ptsmi.co.id/cfind/source/files/sustainable-funding/sustainalytics-second-party-opinion-on-pt-smis-sustainable-funding-framework.pdf https://www.ptsmi.co.id/uk-climate-minister-reviews-pandanduri-micro-hydroelectric-power-plant-appreciates-collaboration-with-pt-smi https://www.flashlombok.com/2025/04/18/pltmh-pandan-duri-diresmikan-dukung-proses-transisi-energi/ https://mentari.info/2023/03/29/uk-government-to-provide-idr-21-billion-through-mentari-programme-for-a-blended-finance-vehicle-with-pt-smi-to-three-hydropower-plants-in-indonesia/

Sheet Step 2
A1: =Instruction!A8 -> Step 2 | B1: =Instruction!B8 -> Map the intermediaries already addressing the issue
A2: Identify the organizations, institutions, and actors already working on the challenge in the target country. This step helps clarify the existing ecosystem, understand who is doing what, and assess which intermediaries may be relevant for partnership, learning, or future engagement by RPA.
A4: Worksheet for Step 2
A5: Country | B5: Project Context | C5: Intermediary | D5: Intermediary Description | E5: Intermediary Role | F5: Sources
A6: Enter the country as in Step 1 | B6: List any current project, policy, or initiative already responding to the issue referring to Step 1 | C6: Name the organization, institution, or actor already involved | D6: Briefly describe the intermediary and its type, such as NGO, foundation, investor, government agency, incubator, DFI, or service provider | E6: Explain what the intermediary is currently doing in relation to the project | F6: Provide credible references for all key data, claims, and examples used in the row
A7: Japan | B7: Toyota City’s “Zutto Genki! Project” | C7: Dream Incubator (DI) | D7: Japanese strategy and business-investment firm that has actively promoted Social Impact Bonds in Japan. DI states that it has been promoting SIBs as a mechanism to address social challenges and worked with Toyota City on the care-prevention SIB initiative. | E7: DI helped structure the Toyota City SIB model. Its materials explain that the Toyota City project aimed to reduce the number of seniors requiring nursing care and to reduce future care costs through social-participation services. | F7: https://www.dreamincubator.co.jp/wp/wp-content/uploads/2022/05/DIREPORT_SIB_EN.pdf https://www.dreamincubator.co.jp/wp-content/uploads/2021/01/210105_SIB_DI_Toyotacity_EN01.pdf
A8: Japan | B8: Toyota City’s “Zutto Genki! Project” | C8: Next Rise Social Impact Action LLC (NRS) | D8: The operating entity in the Toyota City case. DI’s SIB materials state that Next Rise Social Impact Action LLC was contracted by Toyota City to operate and promote the social services under the project from July 1, 2021 to June 30, 2026. | E8: NRS functions as the implementation intermediary. DI’s materials say Toyota City contracted NRS to run and promote the social-participation services and that service providers were selected by NRS. | F8: https://www.dreamincubator.co.jp/wp/wp-content/uploads/2022/05/DIREPORT_SIB_EN.pdf
A9: Japan | B9: Toyota City’s “Zutto Genki! Project” | C9: JAGES (Japan Gerontological Evaluation Study) | D9: A research and evaluation body used in the Toyota City case as part of the evidence and impact-measurement system. Toyota City’s materials link the project to academic evaluation and impact assessment. | E9: JAGES serves as an evidence and evaluation intermediary. In practice, this kind of actor makes preventive-care projects more credible by helping measure whether participation actually changes care-risk and cost outcomes. Toyota City’s public materials explicitly present the project as a privately led preventive-care initiative using the SIB mechanism. | F9: https://www.city.toyota.aichi.jp/_res/projects/default_project/_page_/001/054/238/r0710/01.pdf
A10: Indonesia | B10: Pandanduri Mini Hydro Power Plant | C10: PT Sarana Multi Infrastruktur (PT SMI) | D10: Indonesian state-owned development financing institution and the anchor of SDG Indonesia One. PT SMI describes SDG Indonesia One as a blended-finance platform launched in 2018 that combines philanthropic, donor, bilateral, multilateral, banking, insurance, and other investor funds through development, de-risking, financing, and equity facilities. The Pandanduri Micro Hydro Power Plant (PLTMH Pandanduri) in East Lombok, West Nusa Tenggara, is a small-scale renewable energy project supported through a blended finance structure. Official PT SMI disclosures state that financing disbursed for Pandanduri amounted to IDR 9.6 billion, alongside a Viability Gap Fund (VGF) grant of IDR 2.6 billion. PT SMI’s case-study presentation further indicates a project cost of around IDR 17.3 billion, structured approximately as 55% PT SMI financing, 15% UK MENTARI grant, and 30% project sponsor contribution. | E10: PT SMI is the primary platform intermediary in Indonesia. It does not just lend; it structures blended-finance transactions, supports project development, and manages different facilities under SDG Indonesia One. Pandanduri serves as a project-level demonstration of how catalytic grant funding can unlock debt financing for small renewable energy projects that face commercial feasibility constraints. PT SMI states that the project had been delayed for several years due to commercial feasibility issues, and that the VGF grant helped the project reach financial close and obtain a PT SMI loan. As of March 2025, construction progress had reached 97%, and the project was expected to generate 0.58 MW when operational. This makes Pandanduri a late-construction / near-operation example of SDG Indonesia One-style blended finance in practice. | F10: https://www.ptsmi.co.id/cfind/source/files/annual-report/annual-report-pt-smi-2024.pdf https://www.ptsmi.co.id/uk-climate-minister-reviews-pandanduri-micro-hydroelectric-power-plant-appreciates-collaboration-with-pt-smi https://mentari.info/2023/03/29/uk-government-to-provide-idr-21-billion-through-mentari-programme-for-a-blended-finance-vehicle-with-pt-smi-to-three-hydropower-plants-in-indonesia/ https://www.thkforum.org/wp-content/uploads/2025/07/Delano-Delo-250620-Tri-Hita-Kirana-GBFA-PT-SMI_s-Role-in-Supporting-the-Energy-Transition-in-Indonesia-CLEAN.pdf
A11: Indonesia | B11: Pandanduri Mini Hydro Power Plant | C11: MENTARI | D11: UK-funded clean-energy support programme in Indonesia. Official materials state that MENTARI provided IDR 21 billion in grants to support three hydropower plants with 7 MW total capacity and IDR 210 billion total investment, specifically to improve financial viability and unlock PT SMI financing. | E11: MENTARI functions as a catalytic grant/de-risking intermediary. Its role is not generic donor support; it is targeted at solving bankability barriers in small renewable-energy projects. | F11: https://www.eeas.europa.eu/delegations/indonesia/sdg-indonesia-one_en https://mentari.info/2023/03/29/uk-government-to-provide-idr-21-billion-through-mentari-programme-for-a-blended-finance-vehicle-with-pt-smi-to-three-hydropower-plants-in-indonesia/
A12: Indonesia | B12: Pandanduri Mini Hydro Power Plant | C12: EU support to SDG Indonesia One | D12: The EU Delegation states that its support to PT SMI under SDG Indonesia One included €2 million in grants to target project sponsors facing higher financial barriers and €3 million of technical assistance for project preparation and strategic capacity building at PT SMI, especially to increase the bankability of small renewable-energy projects. | E12: The EU acts as a project-preparation and bankability intermediary, especially through grants plus TA. This is not the same as being the main lender; it is upstream support that helps projects become financeable. | F12: https://www.eeas.europa.eu/delegations/indonesia/sdg-indonesia-one_en

Sheet Step 3
A1: =Instruction!A9 -> Step 3 | B1: =Instruction!B9 -> Diagnose the project stage and barriers
A2: Project stage and barriers primarily derive from the World Economic Forum document titled "Blended Finance Vol. 1: A Primer for Development Finance and Philanthropic Funders," published in 2015. However, because this document might be obsolete in the current situation, we add a new stage, which is the expansion stage, after assessing the Project in Japan. These barriers are subject to change. If the project does not fit in any of these barriers and stages, we can add the relevant stage and barriers.
A4: Barrier Description
A5: Project Stage | B5: Barrier category | C5: Description | D5: Recommended Solutions
A6: Preparing | B6: High upfront costs; binary risk that a project will not happen | C6: Significant initial costs, coupled with uncertain viability and visibility into whether a project will be approved for construction/operation or a company will launch, can cause investors to restrict their capital exposure. | D6: Preparing funding addresses the high upfront costs associated with pre-commissioned projects and feasibility exercises for new businesses. Funding at this stage is most often applicable to large infrastructure projects. It is typically in the form of grants, repayable grants or highly flexible loans.
A7: Pioneering | B7: Early-stage projects with high business model risk; high transaction costs | C7: In very early stage investments where entrepreneurs are experimenting with new ideas, products and business models, it can be difficult for private investors to justify the time and funds to support innovation. | D7: Pioneering funding addresses the high risk and uncertain returns associated with early stage investments, or projects using new technologies or in new markets. It is typically in the form of seed or venture capital that helps entrepreneurs to test and experiment with new ideas, markets, and/or business models.
A8: Facilitating | B8: Sectorial or project risks; returns below commercial rates | C8: Projects and enterprises seeking growth require capital to fund expansion and/or ongoing operations. While they may offer strong development returns at this stage, the risk-adjusted returns for private investors may be below commercial thresholds. | D8: Facilitating funding assists projects and companies that may offer low returns relative to the risks, which investors do not find to be commercially viable. By investing in the riskiest parts of the capital structure, development and philanthropic investors can make the private sector investment more attractive. Direct funding at this stage takes a variety of forms including most often flexible or subordinate debt, i.e. mezzanine, and junior equity.
A9: Anchoring | B9: Macro or sectorial risks; liquidity, refinancing and exit risks | C9: As mature or credible enterprises/projects are seeking capital for scaling or replicating in critical areas of development, capital providers may be hesitant to invest due to real and perceived macro risks, such as political, sectoral and currency risks and uncertainty around exits. | D9: Anchoring funding from a development funder on the same terms as private sector investment can provide comfort to investors, lowering the perceived ability to manage macro risks and increasing the perceived quality of the investment. Anchoring funding can be in the form of either market rate debt or equity.
A10: Transitioning | B10: Lack of local markets knowledge and deal pipeline; inefficient markets | C10: Projects and enterprises at a very mature stage are well suited for commercial viability and access to commercial markets. However, many private investors lack access to a pipeline of deals that are sufficiently sizeable and scalable to fit within investor mandates. | D10: Transitioning funding allows funding pools looking to invest in development sector access to a pipeline of deals that are sufficiently sizeable and scalable to fit within investor mandates.
A11: Expansion | B11: Difficult to monetize social outcomes | C11: The project has been completed or has proven successful, and there is now a desire to expand, replicate, or implement it in new locations or with new target groups. However, the primary benefits of the project are social or public in nature, making it difficult to translate them into cash flows, revenue, or clear payment mechanisms. At this stage, the project does not revert to the "Early Stage," as it already has evidence of its track record, yet it still requires a new structural framework to ensure its social impact effectively supports financing its expansion. | D11: Linking financing to verified outcomes through outcome-based incentives can help scale a proven project whose benefits are primarily social or public. This approach converts measurable impact into a payment logic, allowing foundations, donors, governments, or outcome payers to provide financial incentives once agreed results are achieved.
A13: Worksheet for Step 3
A14: Country | B14: Project Context | C14: Progress Evidence | D14: Project Stage | E14: Project Barrier | F14: Sources
A15: Enter the country as in Step 1 | B15: List any current project, policy, or initiative as in Step 2 | C15: Provide supporting data, facts, or observations that justify the project progress. | D15: Express the project stage according to the actual progress. | E15: Identify the main barrier preventing the project from attracting or mobilizing suitable financing. | F15: Provide credible references for all key data, claims, and examples used in the row
A16: Japan | B16: Toyota City’s “Zutto Genki! Project” | C16: The project’s monetization logic is based primarily on avoided public cost, not on user-paid revenue. The report states that the policy logic was to spend up to JPY 500 million over five years to reduce long-term care insurance expenditure by JPY 1 billion, meaning the financial case depends on proving future fiscal savings rather than selling a product or service directly to participants. The report also identifies causality and measurement as core barriers: long-term care prevention is difficult for social finance because the causal chain is long, and the relationship between program outputs, individual outcomes, and government savings has historically been hard to demonstrate. This links directly to a second barrier: weak short-term returns/long payback periods, because even if the intervention works, savings do not appear immediately and require long-term observation, evaluation, and confidence in future outcome payments. In addition, the report documents local implementation constraints: Toyota City faced administrative capacity pressure during COVID-19 as staff resources were diverted to pandemic countermeasures, and the project still had to build demand for preventive care on the ground. Participation was therefore a live implementation challenge: Year 1 reached 2,603 participants against a nominal annual target of 5,000, although Year 2 rose to 5,838, and cumulative participation reached 8,441. Midterm evaluation nevertheless showed promising evidence that social value could be translated into public savings: the matched analysis estimated approximately JPY 88,000 lower long-term care expenditure per participant and an implied project-level reduction of about JPY 370 million after two years. In summary, the best-fit diagnosis is that this is a socially valuable service-delivery project whose main challenge is not lack of relevance, but the difficulty of converting dispersed public benefits into credible, measurable, and financeable cash-equivalent outcomes at sufficient scale. | D16: =A11 -> Expansion | E16: =B11 -> Difficult to monetize social outcomes | F16: https://www.clair.or.jp/j/library/docs/2021he-toyota.pdf https://www.dreamincubator.com/sea/the-zutto-genki-project-a-500-million-healthy-ageing-social-impact-bond-in-toyota-city/
A17: Indonesia | B17: Pandanduri Mini Hydro Power Plant | C17: The reported 97% construction progress by March 2025 indicates that the project has already passed the main development and financing-closure hurdle. That means the historical bankability barrier was at least partly overcome. The project's current stage is that the remaining concerns lie in project economics and risk-adjusted returns. The case materials show that the project needed a blended structure to move forward: total project cost was reported at about IDR 17.3 billion, with roughly IDR 9.6 billion financed by PT SMI, around IDR 2.6 billion provided through a UK MENTARI grant/viability-gap support window, and the remainder supported by sponsor capital of roughly 30% of project cost. That financing mix suggests that the project’s standalone economics were not strong enough to rely entirely on ordinary commercial terms. For a small hydro asset of roughly 0.58 MW, that is consistent with a returns too low/payback too long barrier: the project can be socially and developmentally useful, but revenue scale may be modest relative to capital cost, making tenor, debt-service capacity, and investor return expectations more difficult to satisfy. A related secondary barrier is downside-risk perception. Even after construction is nearly complete, investors may remain concerned about operating performance, hydrology variability, maintenance, offtake reliability, refinancing conditions, or other factors that could weaken cash flow. Therefore, the best diagnosis for the project’s current stage is not early-stage non-investability, but a late-stage/pre-operation economics-and-risk challenge: the asset appears close to completion, yet its attractiveness to private capital still depends on whether long-payback renewable infrastructure risks are adequately mitigated and whether the expected return is strong enough without over-subsidization. | D17: =A8 -> Facilitating | E17: =B8 -> Sectorial or project risks; returns below commercial rates | F17: https://mentari.info/2023/03/29/uk-government-to-provide-idr-21-billion-through-mentari-programme-for-a-blended-finance-vehicle-with-pt-smi-to-three-hydropower-plants-in-indonesia/ https://www.ptsmi.co.id/uk-climate-minister-reviews-pandanduri-micro-hydroelectric-power-plant-appreciates-collaboration-with-pt-smi https://iati.fcdo.gov.uk/iati_documents/S40039931.pdf https://www.e3s-conferences.org/articles/e3sconf/pdf/2023/105/e3sconf_icstugm2023_10001.pdf

Sheet Step 4
A1: =Instruction!A10 -> Step 4 | B1: =Instruction!B10 -> Recommend blended finance tool
A3: Blended Finance Tools Description
A4: For a foundation acting as a catalytic capital provider, these six tools are sufficient, as they encompass the foundation's primary functions within blended finance: project preparation, bridging viability gaps, mitigating risk, assuming first-loss positions, providing concessional finance, and making results-based payments.
A6: Tool | B6: Description | C6: Best when | D6: Strengths | E6: Weaknesses | F6: Risk Assessment Methodologies
A7: Technical Assistance/Grants | B7: Technical assistance enhances investees' capacity and reduces transaction costs. Grants can also support early-stage project preparation, feasibility studies, and project development capital, for which no repayment is expected. | C7: High upfront costs, limited project readiness, weak sponsor capacity, or a need for early-stage project preparation before private investors can enter. | D7: - Strong fit for early-stage opportunities - Improves project readiness and sponsor capacity - Flexible and adaptable across sectors | E7: - Does not always mobilize capital quickly - Financial impact is indirect at first - Can be too soft if the real barrier is already beyond readiness | F7: 1) Regulatory risk 2) Expected loss
A8: Guarantee/Risk Sharing | B8: Guarantees provide protection against various forms of risk intended to prevent capital losses for investors. Risk-sharing arrangements can cover part of debt service, regulatory risk, off-taker risk, or losses across a portfolio of investments. | C8: Investor hesitation due to credit risk, off-taker risk, regulatory risk, currency risk, or other perceived risks that make the project less attractive. | D8: - Strong mobilization potential - Can crowd in lenders effectively - Targets risk perception directly | E8: - Poor fit if the project is still immature - Can be over-engineered - Requires clear governance, pricing, and claims discipline | F8: 1) Expected loss
A9: First-Loss/Junior Capital | B9: First-loss or junior capital absorbs initial losses or ranks lower in repayment than senior investors. It can take the form of first-loss guarantees, subordinated debt, mezzanine finance, or junior equity, improving the risk-return profile for senior investors. | C9: Need for downside protection, especially in high-risk markets, new technologies, early-stage business models, or projects where crowding-in senior capital is difficult. | D9: - Strong risk absorption - Can unlock more senior capital - Useful for difficult blended structures | E9: - High risk for catalytic funders - Can over-subsidize if the barrier diagnosis is wrong - Structuring can be complex | F9: 1) Expected loss 2) Value-at-risk
A10: Concessional Loans | B10: Concessional loans provide money lent for repayment at a later date, usually with interest, but with favorable terms or rates for the borrower relative to market pricing. These may include below-market interest rates, longer tenors, grace periods, reduced collateral requirements, or deferrals. | C10: Projects requiring debt financing where market-rate capital is too expensive, available tenors are too short, or risk-adjusted returns are below commercial thresholds. | D10: - Helps improve financial viability - Useful for affordability and tenor gaps - Can support scale-up once a project is ready | E10: - Can distort markets if too concessional - Needs strong discipline on subsidy sizing - Not ideal if the real problem is still readiness | F10: 1) Expected loss 2) Discounted cash flow 3) Public-private partnership risk allocation
A11: FX Risk Mitigation/Local Currency Facility | B11: FX risk mitigation protects investors or borrowers against foreign exchange risk. Instruments such as hedging, local currency financing support, or FX liquidity facilities help mitigate exchange-rate volatility and provide access to local or foreign currency during adverse currency movements. | C11: Borrowers earning revenue in local currency while financing is in hard currency, limited or costly hedging instruments, or exchange-rate volatility limiting private investment. | D11: - Highly targeted to FX barriers - Protects borrowers and investors from volatility - Can make otherwise viable deals financeable | E11: - Technical and potentially costly - Does not solve the weak pipeline or poor governance - May be unavailable in some markets | F11: 1) Political Risk
A12: Outcome-Based Incentives | B12: Additional payments are made conditional on the achievement of key performance indicators. Financial incentives are paid out during a pre-agreed, time-bound period to a business that achieves predefined targets, including results-based financing or performance-based incentives. | C12: Clearly measurable and verifiable outcomes, especially where incentives are needed for businesses to pursue new business lines, extend services to underserved segments, or deliver social, environmental, or economic impact. | D12: - Strong accountability and measurement logic - Useful for social systems and public-good outcomes - Can align funding with verified results | E12: - Complex to structure - Requires a credible evaluator and a clear outcome payer - Often involves long time lags before outcomes are verified | F12: 1) Rating agency methodologies
A14: Score Indicators
A15: The indicators are derived from OECD DAC Principle 2 and OECD guidance on evaluating blended finance instruments, mechanisms, and additionality. OECD identifies additionality, mobilisation, concessionality, and commercial sustainability as core concepts for designing blended finance. It also recommends identifying the financing gap, diagnosing the market failure, selecting the financial instrument while minimising concessionality, coordinating with the ecosystem, and monitoring development impact. Therefore, this framework translates those OECD concepts into seven practical screening indicators: barrier fit, mobilisation potential, financial additionality, development additionality, concessionality discipline, implementation feasibility, and impact measurability.
A17: Indicator | B17: Description | C17: Purposes | D17: Important Indicators for Blended Finance Instruments | E17: Guiding scoring question (1-10) | F17: Sources
A18: Barrier fit | B18: Assesses whether the blended finance tool directly addresses the real barrier preventing private capital from entering. The barrier may be project readiness, weak bankability, high perceived risk, low return, affordability constraint, FX risk, information asymmetry, or lack of market track record. | C18: A good tool that targets the wrong barrier is still the wrong intervention. | D18: 1. Technical Assistance/Grants 2. Guarantees/Risk Sharing 3. First-Loss/Junior Capital 4. FX Risk Mitigation/Local Currency Facility 5. Outcome-Based Incentives | E18: Does this tool directly address the diagnosed primary barrier? Identify the exact barrier: is it a readiness gap, viability gap, risk gap, tenor gap, currency gap, affordability gap, or outcome-payment gap? Then check whether the proposed tool solves that barrier. | F18: https://www.oecd.org/content/dam/oecd/en/events/2022/5/cefim_blended-finance-guidance-for-clean-energy---2nd-workshop/Guidance-note-OECD-DAC-Principle-2.pdf
A19: Mobilization potential | B19: Assesses whether the tool can realistically crowd in commercial/private finance. This is not just about the highest leverage ratio, but whether the instrument can make private investors participate in this specific project context. | C19: Mobilisation is central to the rationale for blended finance. | D19: 1. Guarantees/Risk Sharing 2. First-Loss/Junior Capital | E19: How strongly can this tool unlock additional private/commercial finance? Check expected private capital mobilized, type of investors likely to come in, timing of mobilization, and whether mobilization is direct and attributable to the blended finance tool. | F19: https://www.oecd.org/content/dam/oecd/en/publications/reports/2021/08/evaluating-blended-finance-instruments-and-mechanisms_c995f112/f1574c10-en.pdf
A20: Financial additionality | B20: Assesses whether the project truly needs blended finance because commercial capital is unavailable, insufficient, too expensive, too short-term, or not available in the required currency or structure. | C20: Additionality is a core justification for using concessional or catalytic capital. | D20: 1. Guarantees/Risk Sharing 2. First-Loss/Junior Capital 3. Concessional Loans 4. FX Risk Mitigation/Local Currency Facility | E20: Would the deal likely fail, shrink, or worsen without this tool? Can the project obtain financing from private markets on terms, amount, tenor, currency, or risk profile similar to those without foundation support? If yes, blended finance may not be justified. | F20: https://www.oecd.org/content/dam/oecd/en/publications/reports/2021/02/evaluating-financial-and-development-additionality-in-blended-finance-operations_9940d03d/a13bf17d-en.pdf
A21: Development additionality | B21: Assesses whether the intervention creates development impact that would not happen without blended finance. This can include climate impact, inclusion, job creation, access to services, resilience, affordability, or market creation. | C21: Blended finance should improve development contribution, not only financial closure. | D21: 1. Technical Assistance/Grants 2. Outcome-Based Incentives | E21: Does this tool increase the project’s development contribution beyond financing alone? Check the development objective, theory of change, target beneficiaries, expected outcomes, and whether the tool increases the scale, quality, speed, reach, or depth of impact. | F21: https://www.oecd.org/content/dam/oecd/en/publications/reports/2021/02/evaluating-financial-and-development-additionality-in-blended-finance-operations_9940d03d/a13bf17d-en.pdf
A22: Concessionality discipline | B22: Assesses whether the support is sufficiently concessional to unlock private capital, but not more concessional than necessary. It asks whether the subsidy is targeted, minimal, temporary, and justified by the barrier. | C22: OECD stresses minimizing concessionality and targeting market failure precisely. | D22: 1. Guarantees/Risk Sharing 2. First-Loss/Junior Capital 3. Concessional Loans | E22: Is the subsidy proportionate and narrowly targeted to the market failure? Check the subsidy amount, pricing, tenor, guarantee coverage, first-loss amount, grant size, and whether there is a clear rationale for concessionality. Also, ask whether a less concessional tool could work. | F22: https://www.oecd.org/content/dam/oecd/en/events/2022/5/cefim_blended-finance-guidance-for-clean-energy---2nd-workshop/Guidance-note-OECD-DAC-Principle-2.pdf
A23: Implementation feasibility | B23: Assesses whether the instrument can realistically be structured, governed, priced, monitored, and executed in the project’s context. This is especially important for complex tools such as guarantees, hedging, first-loss structures, and outcome-based incentives. | C23: A theoretically strong instrument may fail if it is too difficult to implement. | D23: 1. Technical Assistance/Grants 2. Implementation Feasibility 3. FX Risk Mitigation/Local Currency Facility 4. Outcome-Based Incentives | E23: Can this tool be structured, approved, governed, and implemented in practice? Check whether there are capable implementing partners, legal enforceability, clear triggers, claims process, monitoring systems, data availability, governance, pricing ability, and institutional capacity. | F23: https://www.oecd.org/content/dam/oecd/en/publications/reports/2021/08/evaluating-blended-finance-instruments-and-mechanisms_c995f112/f1574c10-en.pdf
A24: Impact measurability | B24: Assesses whether the expected outcomes can be clearly measured, verified, and monitored. This is especially important for outcome-based incentives, grants, technical assistance, and projects claiming strong development additionality. | C24: Measurement credibility is critical for learning, accountability, and justification. | D24: 1. Technical Assistance/Grants 2. Outcome-Based Incentives | E24: Can outputs, outcomes, and downstream impacts be credibly measured? Check whether the project has measurable KPIs, baseline data, target values, verification method, reporting frequency, and a credible link between the intervention and the outcome. | F24: https://www.oecd.org/content/dam/oecd/en/publications/reports/2021/08/evaluating-blended-finance-instruments-and-mechanisms_c995f112/f1574c10-en.pdf
A26: Project-Level Financial Feasibility Summary
A27: Financial Feasibility Assessment | B27: Project Name
A28: CAPEX / Total Project Cost | B28: Fill in here. If not applicable, write "N/A"
A29: Committed Capital | B29: Fill in here. If not applicable, write "N/A"
A30: Funding Gap | B30: Fill in here. If not applicable, write "N/A"
A31: Revenue or Cost-Saving Source | B31: Fill in here. If not applicable, write "N/A"
A32: NPV | B32: Fill in here. If not applicable, write "N/A"
A33: IRR | B33: Fill in here. If not applicable, write "N/A"
A34: Payback Period | B34: Fill in here. If not applicable, write "N/A"
A35: DSCR | B35: Fill in here. If not applicable, write "N/A"
A36: Grant / Concessional Capital Required | B36: Fill in here. If not applicable, write "N/A"
A37: Capital Mobilization Ratio | B37: Fill in here. If not applicable, write "N/A"
A38: Financial Evidence Status | B38: Fill in here. If not applicable, write "N/A"
A41: Score System
A43: Score | B43: Label | C43: Definition
A44: 1 | B44: Very poor fit | C44: Almost irrelevant on this indicator. The tool does not address the core need and is very unlikely to change the outcome materially.
A45: 2 | B45: Poor fit | C45: There is a slight theoretical connection, but the contribution would be very small and the mismatch is clear.
A46: 3 | B46: Weak | C46: There is limited relevance, but major weaknesses or trade-offs keep it below average.
A47: 4 | B47: Somewhat weak | C47: It can play a partial role, but only for certain sub-problems and with real limitations.
A48: 5 | B48: Moderate / neutral | C48: Reasonably suitable, but not distinctive. The tool could work, yet it has no clear advantage over alternatives.
...

Sheet Step 5
A1: =Instruction!A11 -> Step 5 | B1: =Instruction!B11 -> Recommend a global expansion option for RPA
A3: Global Expansion Option Description
A5: Model | B5: Description | C5: Best When | D5: Pros | E5: Cons | F5: Implementation Implication
A6: Deepen Local | B6: Enhance the capacity of existing local fiscal sponsors and help build regional fiscal sponsorship capability. | C6: A capable local partner already exists and RPA wants to strengthen legitimacy, ownership, and ecosystem depth in one geography. | D6: - Strongest local ownership where capable partners already exist - Builds local legitimacy and ecosystem strength - Good fit for community-based social programs | E6: - Depends on finding capable existing local sponsors - Coverage may stay limited to one or a few jurisdictions | F6: Best suited to contexts where RPA wants to work through and strengthen existing local institutions rather than build new structures from scratch.
A7: Local Repurposing | B7: Support local re-granters to add or adapt fiscal sponsorship functions. | C7: Existing local institutions have adjacent capabilities that can be adapted into fiscal sponsorship or similar support functions. | D7: - Builds local capacity from existing institutions - More local agency than a purely foreign-led model - Can fit places with grantmaking actors, but weak sponsorship infrastructure | E7: - Takes time to adapt systems and governance - May require talent development and process redesign - Geographic coverage can remain limited | F7: Requires adaptation of existing systems, governance, and staffing, with moderate speed and moderate local ownership.
A8: New Build | B8: Create new fiscal sponsorship capacity from scratch in the target geography. | C8: RPA wants maximum control and long-term institution building, and can tolerate the highest setup time and cost. | D8: - Maximum control over mission design and local structure - Strong long-term capacity-building potential - Can be tailored to high-priority geographies | E8: - Slowest route to launch - The highest cost and systems burden - Hardest execution risk in legal, operational, and staffing terms | F8: Most suitable where long-term institution building is the priority and RPA has enough time, budget, and execution capacity.
A9: Local Hybrid | B9: Set up a local organization with local governance and regranting capability, while using RPA / fiscal-sponsor support contractually to accelerate execution. | C9: RPA wants stronger local legitimacy than a pure hybrid while still using its own support model to speed execution. | D9: - Balances local legitimacy with faster execution support - Strong for knowledge transfer and institution building - Closer to local communities than a pure external model | E9: - Still requires some local entity-building from scratch - Not as fast or cheap as a pure hybrid - Coverage may remain selective at first | F9: Useful when RPA needs a balance between local governance, speed, and practical operating support.
A10: Hybrid | B10: Operate through RPA's existing 501(c)(3) / external platform while adding local advisory and operational capacity in the target geography. | C10: RPA wants the fastest and most resource-efficient route to test or support a new geography while retaining some local advisory capacity. | D10: - Fastest practical launch route - Lower setup cost and stronger resource efficiency - Easier to scale across multiple places - Useful when testing a new geography first | E10: - Weaker local ownership than locally anchored models - Can create a Global North perception risk - Requires deliberate safeguards to keep local leadership meaningful | F10: Most suitable for rapid market testing or multi-country expansion where speed and cost efficiency matter more than maximum local ownership.
A12: Score Indicators
A14: Indicator | B14: Description | C14: Purposes | D14: Guiding scoring question (1-10)
A15: Speed | B15: How quickly the model can be launched, staffed, governed, and made operational. | C15: Entry speed matters when opportunities are time-sensitive or when RPA wants to test a market without long setup delays. | D15: How quickly could this model become operational in this country and for this project type?
A16: Cost | B16: Relative resource efficiency, including setup cost, operating cost, and infrastructure burden. | C16: A pathway can look attractive strategically but still be too expensive to build or run. | D16: How resource-efficient is this model relative to the value it could unlock here?
A17: Local Ownership | B17: Extent to which the model embeds local leadership, decision-making, legitimacy, and community agency. | C17: Locally anchored models usually matter more for trust, legitimacy, and long-term durability. | D17: How strongly would this model place leadership and decision-making in local hands?
A18: Scalability | B18: Potential to replicate, expand geographically, and operate across larger volumes or more jurisdictions. | C18: RPA may need a pathway that can move beyond a single pilot site or one relationship. | D18: How easily could this model expand beyond one initial geography or project?
A19: Capacity Building | B19: Ability of the model to strengthen local institutional capability, talent, and ecosystem development. | C19: A stronger model should leave behind local capability, not only deliver transactions. | D19: How much durable local institutional capacity would this model build?
A20: Regulatory Feasibility | B20: How workable the model is within legal, charitable, fiscal, and governance constraints in the target geography. | C20: Even a strong model can fail if the legal or operating pathway is too hard to execute. | D20: How feasible is this model under the country's legal, charitable, tax, and governance context?
A22: Regulatory Assessment
A23: Country / Project | B23: Regulatory assessment area | C23: Relevant regulation / authority | D23: Regulation No. / Year | E23: What RPA needs to check | F23: Why it matters for tool selection | G23: Tool implication | H23: Suggested RPA action | I23: Sources
A24: Fill in here. If not applicable, write "N/A" | B24: Fill in here. If not applicable, write "N/A" | C24: Fill in here. If not applicable, write "N/A" | D24: Fill in here. If not applicable, write "N/A" | E24: Fill in here. If not applicable, write "N/A" | F24: Fill in here. If not applicable, write "N/A" | G24: Fill in here. If not applicable, write "N/A" | H24: Fill in here. If not applicable, write "N/A" | I24: Fill in here. If not applicable, write "N/A"
A25: Fill in here. If not applicable, write "N/A" | B25: Fill in here. If not applicable, write "N/A" | C25: Fill in here. If not applicable, write "N/A" | D25: Fill in here. If not applicable, write "N/A" | E25: Fill in here. If not applicable, write "N/A" | F25: Fill in here. If not applicable, write "N/A" | G25: Fill in here. If not applicable, write "N/A" | H25: Fill in here. If not applicable, write "N/A" | I25: Fill in here. If not applicable, write "N/A"
A26: Fill in here. If not applicable, write "N/A" | B26: Fill in here. If not applicable, write "N/A" | C26: Fill in here. If not applicable, write "N/A" | D26: Fill in here. If not applicable, write "N/A" | E26: Fill in here. If not applicable, write "N/A" | F26: Fill in here. If not applicable, write "N/A" | G26: Fill in here. If not applicable, write "N/A" | H26: Fill in here. If not applicable, write "N/A" | I26: Fill in here. If not applicable, write "N/A"
A27: Fill in here. If not applicable, write "N/A" | B27: Fill in here. If not applicable, write "N/A" | C27: Fill in here. If not applicable, write "N/A" | D27: Fill in here. If not applicable, write "N/A" | E27: Fill in here. If not applicable, write "N/A" | F27: Fill in here. If not applicable, write "N/A" | G27: Fill in here. If not applicable, write "N/A" | H27: Fill in here. If not applicable, write "N/A" | I27: Fill in here. If not applicable, write "N/A"
A28: Fill in here. If not applicable, write "N/A" | B28: Fill in here. If not applicable, write "N/A" | C28: Fill in here. If not applicable, write "N/A" | D28: Fill in here. If not applicable, write "N/A" | E28: Fill in here. If not applicable, write "N/A" | F28: Fill in here. If not applicable, write "N/A" | G28: Fill in here. If not applicable, write "N/A" | H28: Fill in here. If not applicable, write "N/A" | I28: Fill in here. If not applicable, write "N/A"
A29: Fill in here. If not applicable, write "N/A" | B29: Fill in here. If not applicable, write "N/A" | C29: Fill in here. If not applicable, write "N/A" | D29: Fill in here. If not applicable, write "N/A" | E29: Fill in here. If not applicable, write "N/A" | F29: Fill in here. If not applicable, write "N/A" | G29: Fill in here. If not applicable, write "N/A" | H29: Fill in here. If not applicable, write "N/A" | I29: Fill in here. If not applicable, write "N/A"
A30: Fill in here. If not applicable, write "N/A" | B30: Fill in here. If not applicable, write "N/A" | C30: Fill in here. If not applicable, write "N/A" | D30: Fill in here. If not applicable, write "N/A" | E30: Fill in here. If not applicable, write "N/A" | F30: Fill in here. If not applicable, write "N/A" | G30: Fill in here. If not applicable, write "N/A" | H30: Fill in here. If not applicable, write "N/A" | I30: Fill in here. If not applicable, write "N/A"
A31: Fill in here. If not applicable, write "N/A" | B31: Fill in here. If not applicable, write "N/A" | C31: Fill in here. If not applicable, write "N/A" | D31: Fill in here. If not applicable, write "N/A" | E31: Fill in here. If not applicable, write "N/A" | F31: Fill in here. If not applicable, write "N/A" | G31: Fill in here. If not applicable, write "N/A" | H31: Fill in here. If not applicable, write "N/A" | I31: Fill in here. If not applicable, write "N/A"
A32: Fill in here. If not applicable, write "N/A" | B32: Fill in here. If not applicable, write "N/A" | C32: Fill in here. If not applicable, write "N/A" | D32: Fill in here. If not applicable, write "N/A" | E32: Fill in here. If not applicable, write "N/A" | F32: Fill in here. If not applicable, write "N/A" | G32: Fill in here. If not applicable, write "N/A" | H32: Fill in here. If not applicable, write "N/A" | I32: Fill in here. If not applicable, write "N/A"
A35: Score System
A37: Score | B37: Label | C37: Definition
A38: 1 | B38: Very poor fit | C38: Very poor fit on the indicator; major structural weakness.
A39: 2 | B39: Poor fit | C39: Only minimal strengths; severe limitations remain.
A40: 3 | B40: Weak | C40: Below-average performance with clear constraints.
A41: 4 | B41: Somewhat weak | C41: Some usefulness, but notable weaknesses reduce attractiveness.
A42: 5 | B42: Moderate / neutral | C42: Middle-range position; neither clearly weak nor clearly strong.
A43: 6 | B43: Moderately strong | C43: Useful and workable, though not yet a leading option.
A44: 7 | B44: Strong | C44: Strong performance on the criterion in most practical cases.
A45: 8 | B45: Very strong | C45: Highly attractive position with clear comparative advantage.
A46: 9 | B46: Near-optimal | C46: One of the strongest options on this criterion.
A47: 10 | B47: Near-ideal / best fit | C47: Top-end performance; benchmark position within the option set.
A49: Notes:
...

Sheet Sources
A1: Sources
A2: https://www.oecd.org/content/dam/oecd/en/publications/reports/2018/01/making-blended-finance-work-for-the-sustainable-development-goals_g1g88c68/9789264288768-en.pdf
A3: https://www.ifc.org/content/dam/ifc/doc/2025/role-of-blended-finance-in-an-evolving-global-context.pdf
A4: https://www.oecd.org/content/dam/oecd/en/publications/reports/2025/09/oecd-dac-blended-finance-guidance-2025_8ea42fde/e4a13d2c-en.pdf
A5: http://ssrn.com/abstract_id=4770779
A6: https://www.msci-institute.com/wp-content/uploads/2024/10/TMP-Caroline-Flammer-transcript.pdf
A7: https://www.convergence.finance/api/file/e83c0b3ce24e6d07281a4e6fcc8a5516:dc71e6c934fe938f6ff10c1ca73084acba7d1db08eec25042abd5eeda5c7f3aab3171bb67e4e8d237ba934309dbc25ad356afe0d8e6e39d95181107b74722b5bf7c8b53e0c6e3f7aefb6b2ff99a31dc1e538d80375e375f120a6be6bbd50f250dc0eb4719d3d8b0fc04bf97a566c23cc82ca6f3c2984fa22aabb13adf4b213dc09bbcb1dd42a4859ec716d2ffa1b6172659ef318e9ec1b0def8818eb4b50d270
A8: https://www.hhs.se/globalassets/swedish-house-of-finance/conference/annual-conference-2025/presentations/2.-keynote-shof_blended-finance_flammer_09182025.pdf
A9: https://www3.weforum.org/docs/WEF_Blended_Finance_A_Primer_Development_Finance_Philanthropic_Funders.pdf
A10: https://www.nber.org/system/files/working_papers/w32287/w32287.pdf
A11: https://media.unesco.org/sites/default/files/webform/gec003/blended-finance.pdf
A12: https://www.unepfi.org/wordpress/wp-content/uploads/2021/12/NZAOA_Scaling-Blended-Finance.pdf
... A56: https://energyandcleanair.org/wp/wp-content/uploads/2025/09/CREA_EN-IDN-Briefing-Indonesias-RUPTL-2025-2034-Fossils-first-renewables-later.pdf

Sheet Appendix 1
A1: Complete Blended Finance Instruments Description from Commercial and Development Actors
A3: Instruments | B3: Specific Instrument Type | C3: Description | D3: Best when | E3: Sources
